Workbook

Sheet README
B2: HavenInLipa Keyword Tracker
B3: Source: Full SEO Strategy Report (May 8, 2026) + Articles #13 & #14
B4: Prepared by NetCoreSolutions
B6: Purpose
B7: - This workbook is the single source of truth for the keywords HavenInLipa is targeting.
B8: - It is meant to be opened weekly (every Monday), updated from Google Search Console, and used to brief bloggers, editors, and the property team.
B10: What's in each sheet
B11: - 1. README - This sheet. How to use the workbook.
B12: - 2. Keyword Master - The complete keyword list with cluster, intent, priority, target page, status, and tracking columns.
B13: - 3. Priority Focus (60-Day) - The short list of keywords to win in the next 60 days.
B14: - 4. GSC Setup Steps - Exact steps to track these keywords in Google Search Console.
B15: - 5. Blogger Brief - How the blogger should USE these keywords inside articles (no stuffing, no guessing).
... B46: 4. Below the cards, the QUERIES tab is already selected. This lists every search term you appeared for, with its average Position.
A48: KPI baseline reconciliation - 2026-08-14
A49: - Source: calendar-month GSC exports (May 1-31, Jun 1-30, Jul 1-31), Domain property. Daily Chart sums reconcile against BOTH the Countries and Devices tab totals for all three months.
A50: - Verified monthly totals - impressions 910 / 4,295 / 17,218; clicks 12 / 80 / 267; CTR 1.32% / 1.86% / 1.55%; avg position 10.2 / 8.4 / 6.7.
A51: - CORRECTION - Jul clicks were recorded as 244; that is the Philippines row. True total is 267 (244 PH + 23 international).
A52: - CORRECTION - Indexed Pages were recorded 23/28/39; GSC month-end values are 22/35/41. The old '31' was the mid-June reading (Jun 12-29).
A53: - Average Position is impression-weighted from the Devices tab; GSC's own aggregation differs slightly. Labelled derived.
A54: - Top 3/10/100 use ALL queries in the export and are FLOORS (GSC anonymises rare queries - the Jul export holds 115 of 267 clicks, 43%). Geo-qualified equivalents are in the Qualified Reach & Funnel tier.
A55: - 'Geo-qualified' = the query names Lipa, Batangas, or a local landmark (Maculot, Taal, Casa de Segunda, Lomi King...). Jul: 4,914 impressions at 2.26% CTR vs 3,850 generic at 0.10% - so TOTAL impressions is now a vanity metric. Track the geo-qualified row instead.
A56: - Index Coverage Errors stays 1 (one Redirect error). The 39 not-indexed pages are mostly intentional (14 noindex) or benign; the strategic number is 18 'Crawled - currently not indexed', now its own row.
A57: - Still needed: GBP for Aug, Organic Conversions (bookings count - ambiguous, see footnote), GSC Core Web Vitals FIELD data, and the Blog -> Property rows once the Stay Match engine ships.

Sheet KPI Dashboard
A1: HavenInLipa - SEO KPI Dashboard
A2: Monthly performance tracking - paste ~15 numbers once a month; deltas auto-calc. Keyword-level history lives in 'Tracking Log Template'.
A3: KPI | B3: Source / How to pull | C3: 2026-04 | D3: 2026-05 | E3: 2026-06 | F3: 2026-07 | G3: Mid 2026-08 | H3: Δ Jul vs Jun
A4: Leading Indicators (move first, ~2-8 weeks)
A5: Keywords in Top 3 | B5: GSC > Performance > Queries; count position <= 3. Basis: ALL queries in the calendar-month export (a floor — GSC anonymises rare queries). (higher is better) | C5: 6 | D5: 8 | E5: 38 | F5: 115 | H5: =IF(OR(F5="",E5=""),"",F5-E5)
A6: Keywords in Top 10 | B6: GSC > Performance > Queries; count position <= 10. Basis: ALL queries in export (floor). (higher is better) | C6: 9 | D6: 26 | E6: 128 | F6: 494 | H6: =IF(OR(F6="",E6=""),"",F6-E6)
A7: Keywords in Top 100 | B7: GSC > Performance > Queries; count position <= 100. Basis: ALL queries in export (floor). (higher is better) | C7: 10 | D7: 70 | E7: 189 | F7: 607 | H7: =IF(OR(F7="",E7=""),"",F7-E7)
A8: Total Impressions (28d) | B8: GSC > Performance > last 28 days > Total impressions (higher is better) | C8: 41 | D8: 910 | E8: 4295 | F8: 17218 | H8: =IF(OR(F8="",E8=""),"",F8-E8)
A9: Indexed Pages | B9: GSC > Pages (Indexing) > Indexed count (or Page Indexing Tracker) (higher is better) | C9: 4 | D9: 22 | E9: 35 | F9: 41 | G9: 41 | H9: =IF(OR(F9="",E9=""),"",F9-E9)
A10: Traffic & Engagement (~1-4 months)
A11: Non-branded Organic Clicks | B11: GSC > Performance > 'Queries not containing' brand filter > Clicks. 2026-05..07 are DERIVED = total clicks, because branded terms drew ZERO clicks in all three months. (higher is better) | C11: 0 | D11: 12 | E11: 80 | F11: 267 | H11: =IF(OR(F11="",E11=""),"",F11-E11)
A12: Total Organic Clicks (28d) | B12: GSC > Performance > last 28 days > Total clicks (higher is better) | C12: 2 | D12: 12 | E12: 80 | F12: 267 | H12: =IF(OR(F12="",E12=""),"",F12-E12)
A13: Organic CTR % | B13: GSC > Performance > Average CTR (higher is better) | C13: 0.049 | D13: 0.0132 | E13: 0.0186 | F13: 0.0155 | H13: =IF(OR(F13="",E13=""),"",F13-E13)
A14: Average Position | B14: GSC > Performance > Average position. 2026-05..07 recomputed impression-weighted from the Devices tab (derived). (lower is better) | C14: 8.4 | D14: 10.2 | E14: 8.4 | F14: 6.7 | H14: =IF(OR(F14="",E14=""),"",F14-E14)
A15: Local / Conversion - Google Business Profile
A16: GBP Calls | B16: GBP > Performance > Calls (monthly) (higher is better) | C16: 0 | D16: 1 | E16: 4 | F16: 0 | H16: =IF(OR(F16="",E16=""),"",F16-E16)
A17: GBP Direction Requests | B17: GBP > Performance > Directions (higher is better) | C17: 43 | D17: 32 | E17: 49 | F17: 65 | H17: =IF(OR(F17="",E17=""),"",F17-E17)
A18: GBP Website Clicks | B18: GBP > Performance > Website clicks (higher is better) | C18: 1 | D18: 1 | E18: 1 | F18: 0 | H18: =IF(OR(F18="",E18=""),"",F18-E18)
A19: GBP Profile Views | B19: GBP > Performance > Views (search + maps) (higher is better) | C19: 150 | D19: 158 | E19: 153 | F19: 238 | H19: =IF(OR(F19="",E19=""),"",F19-E19)
A20: Guardrails (regressions here silently kill the rest)
A21: Core Web Vitals (Pass/Fail) | B21: GSC > Core Web Vitals (FIELD data). NOTE: 2026-08 'Pass' is from PageSpeed LAB data (98 mobile / 100 desktop) — GSC field data may read 'insufficient data' at this traffic level. | C21: Needs work | D21: Needs work | E21: Pass | F21: Pass | G21: Pass
A22: Index Coverage Errors | B22: GSC > Pages (Indexing) > ERROR count only (currently 1 Redirect error). Total not-indexed is a different metric — see the Qualified Reach & Funnel tier. (lower is better) | C22: 0 | D22: 1 | E22: 1 | F22: 1 | G22: 1 | H22: =IF(OR(F22="",E22=""),"",F22-E22)
A24: Conversion Outcomes (GA4) - the numbers that prove ROI
A25: Organic Conversions (bookings + inquiries) | B25: GA4 > Key events (booking_confirmed + generate_lead), Organic segment (see Conversion Fix #3). Enter monthly. | H25: =IF(OR(F25="",E25=""),"",F25-E25)
A26: Organic Conversion Rate | C26: =IF(OR(C25="",C12="",C12=0),"",C25/C12) | D26: =IF(OR(D25="",D12="",D12=0),"",D25/D12) | E26: =IF(OR(E25="",E12="",E12=0),"",E25/E12) | F26: =IF(OR(F25="",F12="",F12=0),"",F25/F12) | H26: =IF(OR(F26="",E26=""),"",F26-E26)
A28: Qualified Reach & Funnel (added 2026-08-14) - is the reach REAL, and does it reach the booking pages?
A29: Geo-qualified Impressions | B29: GSC > Performance > filter Query CONTAINS "lipa" > Impressions (calendar month; export basis = floor). (higher is better) | D29: 181 | E29: 1254 | F29: 4914 | H29: =IF(OR(F29="",E29=""),"",F29-E29)
A30: Geo-qualified Clicks | B30: Same "lipa" query filter > Clicks. THE real reach number (export basis = floor). (higher is better) | D30: 0 | E30: 12 | F30: 111 | H30: =IF(OR(F30="",E30=""),"",F30-E30)
A31: Geo-qualified CTR % | B31: Auto = Geo-qualified Clicks / Geo-qualified Impressions. Jul was 2.26% vs 0.10% on generic queries - a 23x gap. (higher is better) | C31: =IF(OR(C30="",C29="",C29=0),"",C30/C29) | D31: =IF(OR(D30="",D29="",D29=0),"",D30/D29) | E31: =IF(OR(E30="",E29="",E29=0),"",E30/E29) | F31: =IF(OR(F30="",F29="",F29=0),"",F30/F29) | G31: =IF(OR(G30="",G29="",G29=0),"",G30/G29) | H31: =IF(OR(F31="",E31=""),"",F31-E31)
A32: Geo-qualified Keywords in Top 10 | B32: Queries export, geo-qualified rows only, position <= 10. Better "tracked set" proxy than the all-query count above. (higher is better) | D32: 13 | E32: 74 | F32: 199 | H32: =IF(OR(F32="",E32=""),"",F32-E32)
A33: Generic (non-geo) Impressions | B33: Queries export rows NOT naming Lipa/Batangas/a local landmark ("best restaurants near me", foreign-language food queries). Dilution watch - inflates total impressions at ~0.1% CTR. (lower is better) | D33: 79 | E33: 223 | F33: 3850 | H33: =IF(OR(F33="",E33=""),"",F33-E33)
A34: Crawled - currently not indexed | B34: GSC > Pages (Indexing) > "Crawled - currently not indexed". Google crawled these and declined to index them. Current-day snapshot. (lower is better) | G34: 18 | H34: =IF(OR(F34="",E34=""),"",F34-E34)
A35: Blog -> Property Clicks | B35: GA4 stay_match_click + property-link clicks from blog articles. Requires the Stay Match engine (brief pending). (higher is better) | H35: =IF(OR(F35="",E35=""),"",F35-E35)
A36: Blog -> Property CTR % | B36: Auto = Blog -> Property Clicks / Total Organic Clicks (row 12). The hand-off rate: Jul was ~1.9% by page-level proxy. (higher is better) | C36: =IF(OR(C35="",C12="",C12=0),"",C35/C12) | D36: =IF(OR(D35="",D12="",D12=0),"",D35/D12) | E36: =IF(OR(E35="",E12="",E12=0),"",E35/E12) | F36: =IF(OR(F35="",F12="",F12=0),"",F35/F12) | G36: =IF(OR(G35="",G12="",G12=0),"",G35/G12) | H36: =IF(OR(F36="",E36=""),"",F36-E36)
A37: Stay-Match Click Rate % | B37: GA4 stay_match_click / stay_match_view. Break down by the confidence param in GA4 to retune the scoring weights monthly. (higher is better) | H37: =IF(OR(F37="",E37=""),"",F37-E37)
A39: Δ Jul vs Jun = last two COMPLETE months (F minus E). The 'Mid 2026-08' column is a partial-month/current-day snapshot and is deliberately excluded from the delta. Green = improving; direction-aware (for Average Position, Index Coverage Errors, Crawled-not-indexed and Generic Impressions, LOWER is better). | Pull-window rule: Performance rows are date-ranged to the calendar month; Indexed Pages, Index Coverage Errors, Crawled-not-indexed and Core Web Vitals are current-day snapshots. | 2026-08-14 reconciliation: Jul clicks 244->267 (244 was the Philippines row, not the total); Indexed Pages 23/28/39->22/35/41 (GSC month-end); query-level rows are FLOORS because GSC anonymises rare queries (the Jul export holds 115 of 267 clicks). Organic Conversions intentionally left blank pending Cedric: '2 bookings' is ambiguous between 2 total across 3 months and ~2/month.

Sheet Cluster KPIs
A1: Cluster KPIs - auto-rollup from Keyword Master
A2: 100% formula-driven. Reflects the latest 28-day snapshot pasted into Keyword Master - no manual entry here.
A3: Cluster | B3: Clicks (28d) | C3: Impressions (28d) | D3: Avg Position | E3: # Keywords | F3: # in Top 10
A4: Cluster 1 - Short-Term Rentals | B4: =SUMIF('Keyword Master'!$B$2:$B$83,A4,'Keyword Master'!$N$2:$N$83) | C4: =SUMIF('Keyword Master'!$B$2:$B$83,A4,'Keyword Master'!$M$2:$M$83) | D4: =IFERROR(AVERAGEIFS('Keyword Master'!$K$2:$K$83,'Keyword Master'!$B$2:$B$83,A4,'Keyword Master'!$K$2:$K$83,">0"),"-") | E4: =COUNTIF('Keyword Master'!$B$2:$B$83,A4) | F4: =COUNTIFS('Keyword Master'!$B$2:$B$83,A4,'Keyword Master'!$K$2:$K$83,">0",'Keyword Master'!$K$2:$K$83,"<=10")
A5: Cluster 2 - Things to Do in Lipa | B5: =SUMIF('Keyword Master'!$B$2:$B$83,A5,'Keyword Master'!$N$2:$N$83) | C5: =SUMIF('Keyword Master'!$B$2:$B$83,A5,'Keyword Master'!$M$2:$M$83) | D5: =IFERROR(AVERAGEIFS('Keyword Master'!$K$2:$K$83,'Keyword Master'!$B$2:$B$83,A5,'Keyword Master'!$K$2:$K$83,">0"),"-") | E5: =COUNTIF('Keyword Master'!$B$2:$B$83,A5) | F5: =COUNTIFS('Keyword Master'!$B$2:$B$83,A5,'Keyword Master'!$K$2:$K$83,">0",'Keyword Master'!$K$2:$K$83,"<=10")
A6: Cluster 3 - Weekend Getaway / Audience | B6: =SUMIF('Keyword Master'!$B$2:$B$83,A6,'Keyword Master'!$N$2:$N$83) | C6: =SUMIF('Keyword Master'!$B$2:$B$83,A6,'Keyword Master'!$M$2:$M$83) | D6: =IFERROR(AVERAGEIFS('Keyword Master'!$K$2:$K$83,'Keyword Master'!$B$2:$B$83,A6,'Keyword Master'!$K$2:$K$83,">0"),"-") | E6: =COUNTIF('Keyword Master'!$B$2:$B$83,A6) | F6: =COUNTIFS('Keyword Master'!$B$2:$B$83,A6,'Keyword Master'!$K$2:$K$83,">0",'Keyword Master'!$K$2:$K$83,"<=10")
A7: Cluster 4 - Travel Planning & Logistics | B7: =SUMIF('Keyword Master'!$B$2:$B$83,A7,'Keyword Master'!$N$2:$N$83) | C7: =SUMIF('Keyword Master'!$B$2:$B$83,A7,'Keyword Master'!$M$2:$M$83) | D7: =IFERROR(AVERAGEIFS('Keyword Master'!$K$2:$K$83,'Keyword Master'!$B$2:$B$83,A7,'Keyword Master'!$K$2:$K$83,">0"),"-") | E7: =COUNTIF('Keyword Master'!$B$2:$B$83,A7) | F7: =COUNTIFS('Keyword Master'!$B$2:$B$83,A7,'Keyword Master'!$K$2:$K$83,">0",'Keyword Master'!$K$2:$K$83,"<=10")
A8: Cluster 5 - Direct Booking & Value | B8: =SUMIF('Keyword Master'!$B$2:$B$83,A8,'Keyword Master'!$N$2:$N$83) | C8: =SUMIF('Keyword Master'!$B$2:$B$83,A8,'Keyword Master'!$M$2:$M$83) | D8: =IFERROR(AVERAGEIFS('Keyword Master'!$K$2:$K$83,'Keyword Master'!$B$2:$B$83,A8,'Keyword Master'!$K$2:$K$83,">0"),"-") | E8: =COUNTIF('Keyword Master'!$B$2:$B$83,A8) | F8: =COUNTIFS('Keyword Master'!$B$2:$B$83,A8,'Keyword Master'!$K$2:$K$83,">0",'Keyword Master'!$K$2:$K$83,"<=10")
A9: Cluster 6 - Branded / Property | B9: =SUMIF('Keyword Master'!$B$2:$B$83,A9,'Keyword Master'!$N$2:$N$83) | C9: =SUMIF('Keyword Master'!$B$2:$B$83,A9,'Keyword Master'!$M$2:$M$83) | D9: =IFERROR(AVERAGEIFS('Keyword Master'!$K$2:$K$83,'Keyword Master'!$B$2:$B$83,A9,'Keyword Master'!$K$2:$K$83,">0"),"-") | E9: =COUNTIF('Keyword Master'!$B$2:$B$83,A9) | F9: =COUNTIFS('Keyword Master'!$B$2:$B$83,A9,'Keyword Master'!$K$2:$K$83,">0",'Keyword Master'!$K$2:$K$83,"<=10")
A10: TOTAL / All clusters | B10: =SUM(B4:B9) | C10: =SUM(C4:C9) | D10: =IFERROR(AVERAGEIFS('Keyword Master'!$K$2:$K$83,'Keyword Master'!$K$2:$K$83,">0"),"-") | E10: =SUM(E4:E9) | F10: =SUM(F4:F9)

Sheet Keyword Master
A1: Keyword / Keyphrase | B1: Cluster | C1: Search Intent | D1: Priority | E1: Role | F1: Target URL / Page | G1: Confirmed Live Slug | H1: Article | I1: Status | J1: GSC Tracked? (Y/N) | K1: Current Avg. Position | L1: Striking Distance? | M1: Impressions (28d) | N1: Clicks (28d) | O1: CTR % | P1: Last Reviewed | Q1: Notes
A2: things to do in lipa city | B2: Cluster 2 - Things to Do in Lipa | C2: Informational | D2: High | E2: Primary | F2: https://blog.haveninlipa.com/15-best-things-to-do-in-lipa-city-batangas-2026-locals-guide/ | G2: https://blog.haveninlipa.com/15-best-things-to-do-in-lipa-city-batangas-2026-locals-guide/ | H2: 1 | I2: Published | J2: Y | K2: 17.9 | L2: =IF(AND(K2>=11,K2<=20),"Striking distance","") | M2: 167 | N2: 0 | O2: 0 | P2: 46244 | Q2: Target URL synced to live slug + confirmed indexed (GSC) 2026-06-02.
A3: lipa city tourist spots | B3: Cluster 2 - Things to Do in Lipa | C3: Informational | D3: High | E3: Secondary | F3: https://blog.haveninlipa.com/15-best-things-to-do-in-lipa-city-batangas-2026-locals-guide/ | G3: https://blog.haveninlipa.com/15-best-things-to-do-in-lipa-city-batangas-2026-locals-guide/ | H3: 1 | I3: Published | J3: Y | K3: 0 | L3: =IF(AND(K3>=11,K3<=20),"Striking distance","") | M3: 0 | N3: 0 | O3: 0 | P3: 46244 | Q3: Target URL synced to live slug + confirmed indexed (GSC) 2026-06-02.
A4: lipa batangas attractions | B4: Cluster 2 - Things to Do in Lipa | C4: Informational | D4: Medium | E4: Secondary | F4: https://blog.haveninlipa.com/15-best-things-to-do-in-lipa-city-batangas-2026-locals-guide/ | G4: https://blog.haveninlipa.com/15-best-things-to-do-in-lipa-city-batangas-2026-locals-guide/ | H4: 1 | I4: Published | J4: Y | K4: 0 | L4: =IF(AND(K4>=11,K4<=20),"Striking distance","") | M4: 0 | N4: 0 | O4: 0 | P4: 46244 | Q4: Target URL synced to live slug + confirmed indexed (GSC) 2026-06-02.
A5: weekend getaway near manila | B5: Cluster 3 - Weekend Getaway / Audience | C5: Mixed | D5: High | E5: Primary | F5: https://blog.haveninlipa.com/weekend-getaway-in-lipa-city-batangas-your-chill-escape-near-manila/ | G5: https://blog.haveninlipa.com/weekend-getaway-in-lipa-city-batangas-your-chill-escape-near-manila/ | H5: 3 | I5: Published | J5: Y | K5: 11 | L5: =IF(AND(K5>=11,K5<=20),"Striking distance","") | M5: 1 | N5: 0 | O5: 0 | P5: 46244 | Q5: Target URL synced to live slug + confirmed indexed (GSC) 2026-06-02.
A6: mt maculot hiking guide | B6: Cluster 2 - Things to Do in Lipa | C6: Informational | D6: Medium | E6: Primary | F6: https://blog.haveninlipa.com/mt-maculot-hiking-guide-2026-trail-tips-routes-where-to-stay-in-lipa/ | G6: https://blog.haveninlipa.com/mt-maculot-hiking-guide-2026-trail-tips-routes-where-to-stay-in-lipa/ | H6: 4 | I6: Published | J6: Y | K6: 0 | L6: =IF(AND(K6>=11,K6<=20),"Striking distance","") | M6: 0 | N6: 0 | O6: 0 | P6: 46244 | Q6: Target URL synced to live slug + confirmed indexed (GSC) 2026-06-02.
A7: best restaurants in lipa | B7: Cluster 4 - Travel Planning & Logistics | C7: Informational | D7: High | E7: Primary | F7: https://blog.haveninlipa.com/best-restaurants-cafes-in-lipa-city-batangas-2026-food-guide/ | G7: https://blog.haveninlipa.com/best-restaurants-cafes-in-lipa-city-batangas-2026-food-guide/ | H7: 5 | I7: Published | J7: Y | K7: 5.1 | L7: =IF(AND(K7>=11,K7<=20),"Striking distance","") | M7: 335 | N7: 16 | O7: 0.048 | P7: 46244 | Q7: Target URL synced to live slug + confirmed indexed (GSC) 2026-06-02.
A8: lipa city food trip | B8: Cluster 4 - Travel Planning & Logistics | C8: Informational | D8: Medium | E8: Secondary | F8: https://blog.haveninlipa.com/best-restaurants-cafes-in-lipa-city-batangas-2026-food-guide/ | G8: https://blog.haveninlipa.com/best-restaurants-cafes-in-lipa-city-batangas-2026-food-guide/ | H8: 5 | I8: Published | J8: Y | K8: 0 | L8: =IF(AND(K8>=11,K8<=20),"Striking distance","") | M8: 0 | N8: 0 | O8: 0 | P8: 46244 | Q8: Target URL synced to live slug + confirmed indexed (GSC) 2026-06-02.
A9: airbnb alternative lipa | B9: Cluster 1 - Short-Term Rentals | C9: Transactional | D9: High | E9: Primary | F9: https://blog.haveninlipa.com/why-book-direct-instead-of-airbnb-a-philippines-hosts-honest-take/ | G9: https://blog.haveninlipa.com/why-book-direct-instead-of-airbnb-a-philippines-hosts-honest-take/ | H9: 6 | I9: Published | J9: Y | K9: 0 | L9: =IF(AND(K9>=11,K9<=20),"Striking distance","") | M9: 0 | N9: 0 | O9: 0 | P9: 46244 | Q9: Target URL synced to live slug + confirmed indexed (GSC) 2026-06-02.
A10: direct booking lipa city | B10: Cluster 1 - Short-Term Rentals | C10: Commercial | D10: Medium | E10: Secondary | F10: https://blog.haveninlipa.com/why-book-direct-instead-of-airbnb-a-philippines-hosts-honest-take/ | G10: https://blog.haveninlipa.com/why-book-direct-instead-of-airbnb-a-philippines-hosts-honest-take/ | H10: 6 | I10: Published | J10: Y | K10: 0 | L10: =IF(AND(K10>=11,K10<=20),"Striking distance","") | M10: 0 | N10: 0 | O10: 0 | P10: 46244 | Q10: Target URL synced to live slug + confirmed indexed (GSC) 2026-06-02.
A11: book direct vs airbnb | B11: Cluster 5 - Direct Booking & Value | C11: Commercial | D11: High | E11: Secondary | F11: https://blog.haveninlipa.com/why-book-direct-instead-of-airbnb-a-philippines-hosts-honest-take/ | G11: https://blog.haveninlipa.com/why-book-direct-instead-of-airbnb-a-philippines-hosts-honest-take/ | H11: 6 | I11: Published | J11: Y | K11: 0 | L11: =IF(AND(K11>=11,K11<=20),"Striking distance","") | M11: 0 | N11: 0 | O11: 0 | P11: 46244 | Q11: Target URL synced to live slug + confirmed indexed (GSC) 2026-06-02.
A12: save on vacation rental fees | B12: Cluster 5 - Direct Booking & Value | C12: Commercial | D12: Medium | E12: Secondary | F12: https://blog.haveninlipa.com/why-book-direct-instead-of-airbnb-a-philippines-hosts-honest-take/ | G12: https://blog.haveninlipa.com/why-book-direct-instead-of-airbnb-a-philippines-hosts-honest-take/ | H12: 6 | I12: Published | J12: Y | K12: 0 | L12: =IF(AND(K12>=11,K12<=20),"Striking distance","") | M12: 0 | N12: 0 | O12: 0 | P12: 46244 | Q12: Target URL synced to live slug + confirmed indexed (GSC) 2026-06-02.
A13: why book direct accommodation | B13: Cluster 5 - Direct Booking & Value | C13: Commercial | D13: Medium | E13: Secondary | F13: https://blog.haveninlipa.com/why-book-direct-instead-of-airbnb-a-philippines-hosts-honest-take/ | G13: https://blog.haveninlipa.com/why-book-direct-instead-of-airbnb-a-philippines-hosts-honest-take/ | H13: 6 | I13: Published | J13: Y | K13: 0 | L13: =IF(AND(K13>=11,K13<=20),"Striking distance","") | M13: 0 | N13: 0 | O13: 0 | P13: 46244 | Q13: Target URL synced to live slug + confirmed indexed (GSC) 2026-06-02.
A14: taal volcano day trip from lipa | B14: Cluster 2 - Things to Do in Lipa | C14: Informational | D14: Medium | E14: Primary | F14: https://blog.haveninlipa.com/taal-volcano-day-trip-from-lipa-city-2026-updated-guide/ | G14: https://blog.haveninlipa.com/taal-volcano-day-trip-from-lipa-city-2026-updated-guide/ | H14: 7 | I14: Published | J14: Y | K14: 0 | L14: =IF(AND(K14>=11,K14<=20),"Striking distance","") | M14: 0 | N14: 0 | O14: 0 | P14: 46244 | Q14: Target URL synced to live slug + confirmed indexed (GSC) 2026-06-02.
A15: holy week getaway lipa | B15: Cluster 3 - Weekend Getaway / Audience | C15: Seasonal | D15: Medium | E15: Primary | F15: https://blog.haveninlipa.com/holy-week-in-lipa-city-batangas-a-peaceful-retreat-near-manila/ | G15: https://blog.haveninlipa.com/holy-week-in-lipa-city-batangas-a-peaceful-retreat-near-manila/ | H15: 8 | I15: Published | J15: Y | K15: 0 | L15: =IF(AND(K15>=11,K15<=20),"Striking distance","") | M15: 0 | N15: 0 | O15: 0 | P15: 46244
A16: remote work staycation philippines | B16: Cluster 3 - Weekend Getaway / Audience | C16: Commercial | D16: Medium | E16: Primary | F16: https://blog.haveninlipa.com/work-from-lipa-the-affordable-remote-work-staycation-near-manila/ | G16: https://blog.haveninlipa.com/work-from-lipa-the-affordable-remote-work-staycation-near-manila/ | H16: 9 | I16: Published | J16: Y | K16: 0 | L16: =IF(AND(K16>=11,K16<=20),"Striking distance","") | M16: 0 | N16: 0 | O16: 0 | P16: 46244 | Q16: Target URL synced to live slug + confirmed indexed (GSC) 2026-06-02.
A17: how to get to lipa from manila | B17: Cluster 4 - Travel Planning & Logistics | C17: Informational | D17: Medium | E17: Primary | F17: https://blog.haveninlipa.com/how-to-get-to-lipa-city-from-manila-2026-guide/ | G17: https://blog.haveninlipa.com/how-to-get-to-lipa-city-from-manila-2026-guide/ | H17: 10 | I17: Published | J17: Y | K17: 0 | L17: =IF(AND(K17>=11,K17<=20),"Striking distance","") | M17: 0 | N17: 0 | O17: 0 | P17: 46244 | Q17: Target URL synced to live slug + confirmed indexed (GSC) 2026-06-02.
A18: family staycation lipa | B18: Cluster 3 - Weekend Getaway / Audience | C18: Commercial | D18: High | E18: Primary | F18: https://blog.haveninlipa.com/family-staycation-lipa/ | G18: https://blog.haveninlipa.com/family-staycation-lipa-city-batangas/ | H18: 11 | I18: Published | J18: Y | K18: 0 | L18: =IF(AND(K18>=11,K18<=20),"Striking distance","") | M18: 0 | N18: 0 | O18: 0 | P18: 46244
A19: family-friendly rental lipa city | B19: Cluster 3 - Weekend Getaway / Audience | C19: Commercial | D19: High | E19: Secondary | F19: https://blog.haveninlipa.com/family-staycation-lipa/ | G19: https://blog.haveninlipa.com/family-staycation-lipa-city-batangas/ | H19: 11 | I19: Published | J19: Y | K19: 0 | L19: =IF(AND(K19>=11,K19<=20),"Striking distance","") | M19: 0 | N19: 0 | O19: 0 | P19: 46244
A20: weekend getaway with kids near manila | B20: Cluster 3 - Weekend Getaway / Audience | C20: Commercial | D20: High | E20: Secondary | F20: https://blog.haveninlipa.com/family-staycation-lipa/ | G20: https://blog.haveninlipa.com/family-staycation-lipa-city-batangas/ | H20: 11 | I20: Published | J20: Y | K20: 0 | L20: =IF(AND(K20>=11,K20<=20),"Striking distance","") | M20: 0 | N20: 0 | O20: 0 | P20: 46244
A21: kid-friendly batangas | B21: Cluster 3 - Weekend Getaway / Audience | C21: Informational | D21: Medium | E21: Secondary | F21: https://blog.haveninlipa.com/family-staycation-lipa/ | G21: https://blog.haveninlipa.com/family-staycation-lipa-city-batangas/ | H21: 11 | I21: Published | J21: Y | K21: 0 | L21: =IF(AND(K21>=11,K21<=20),"Striking distance","") | M21: 0 | N21: 0 | O21: 0 | P21: 46244
A22: romantic getaway batangas | B22: Cluster 3 - Weekend Getaway / Audience | C22: Commercial | D22: High | E22: Primary | F22: https://blog.haveninlipa.com/romantic-getaway-batangas/ | G22: https://blog.haveninlipa.com/romantic-getaway-batangas-lipa-city/ | H22: 12 | I22: Published | J22: Y | K22: 0 | L22: =IF(AND(K22>=11,K22<=20),"Striking distance","") | M22: 0 | N22: 0 | O22: 0 | P22: 46244
A23: couple retreat lipa | B23: Cluster 3 - Weekend Getaway / Audience | C23: Commercial | D23: High | E23: Secondary | F23: https://blog.haveninlipa.com/romantic-getaway-batangas/ | G23: https://blog.haveninlipa.com/romantic-getaway-batangas-lipa-city/ | H23: 12 | I23: Published | J23: Y | K23: 0 | L23: =IF(AND(K23>=11,K23<=20),"Striking distance","") | M23: 0 | N23: 0 | O23: 0 | P23: 46244
A24: honeymoon batangas | B24: Cluster 3 - Weekend Getaway / Audience | C24: Commercial | D24: Medium | E24: Secondary | F24: https://blog.haveninlipa.com/romantic-getaway-batangas/ | G24: https://blog.haveninlipa.com/romantic-getaway-batangas-lipa-city/ | H24: 12 | I24: Published | J24: Y | K24: 0 | L24: =IF(AND(K24>=11,K24<=20),"Striking distance","") | M24: 0 | N24: 0 | O24: 0 | P24: 46244
A25: anniversary getaway near manila | B25: Cluster 3 - Weekend Getaway / Audience | C25: Commercial | D25: Medium | E25: Secondary | F25: https://blog.haveninlipa.com/romantic-getaway-batangas/ | G25: https://blog.haveninlipa.com/romantic-getaway-batangas-lipa-city/ | H25: 12 | I25: Published | J25: Y | K25: 0 | L25: =IF(AND(K25>=11,K25<=20),"Striking distance","") | M25: 0 | N25: 0 | O25: 0 | P25: 46244
A26: full house rental lipa | B26: Cluster 1 - Short-Term Rentals | C26: Transactional | D26: High | E26: Primary | F26: https://haveninlipa.com/properties/mickey-in-lipa--full-family-house--sleeps-15 | G26: https://haveninlipa.com/properties/mickey-in-lipa--full-family-house--sleeps-15 | H26: 13 | I26: Live - verify GSC | J26: Y | K26: 0 | L26: =IF(AND(K26>=11,K26<=20),"Striking distance","") | M26: 0 | N26: 0 | O26: 0 | P26: 46244 | Q26: Transactional → Full Family House (sleeps 15). Mapped to booking page, not blog, 2026-06-18.
A27: family house rental lipa city | B27: Cluster 1 - Short-Term Rentals | C27: Transactional | D27: High | E27: Primary | F27: https://haveninlipa.com/properties/mickey-in-lipa--family-house--sleeps-11 | G27: https://haveninlipa.com/properties/mickey-in-lipa--family-house--sleeps-11 | H27: 13 | I27: Live - verify GSC | J27: Y | K27: 0 | L27: =IF(AND(K27>=11,K27<=20),"Striking distance","") | M27: 0 | N27: 0 | O27: 0 | P27: 46244 | Q27: Transactional → Family House (sleeps 11). Mapped to booking page, not blog, 2026-06-18.
A28: mickey in lipa | B28: Cluster 6 - Branded / Property | C28: Branded | D28: High | E28: Primary | F28: https://blog.haveninlipa.com/mickey-in-lipa-coming-soon/ | G28: https://blog.haveninlipa.com/mickey-in-lipa-coming-soon/ | H28: 13 | I28: Published | J28: Y | K28: 0 | L28: =IF(AND(K28>=11,K28<=20),"Striking distance","") | M28: 0 | N28: 0 | O28: 0 | P28: 46244 | Q28: Branded → launch post hub (links all 3 configs). 2026-06-18.
A29: disney-inspired house lipa | B29: Cluster 6 - Branded / Property | C29: Commercial | D29: High | E29: Secondary | F29: https://blog.haveninlipa.com/mickey-in-lipa-coming-soon/ | G29: https://blog.haveninlipa.com/mickey-in-lipa-coming-soon/ | H29: 13 | I29: Published | J29: Y | K29: 0 | L29: =IF(AND(K29>=11,K29<=20),"Striking distance","") | M29: 0 | N29: 0 | O29: 0 | P29: 46244 | Q29: Commercial → launch post hub. 2026-06-18.
A30: disney themed rental philippines | B30: Cluster 6 - Branded / Property | C30: Commercial | D30: Medium | E30: Secondary | F30: https://blog.haveninlipa.com/mickey-in-lipa-coming-soon/ | G30: https://blog.haveninlipa.com/mickey-in-lipa-coming-soon/ | H30: 13 | I30: Published | J30: Y | K30: 0 | L30: =IF(AND(K30>=11,K30<=20),"Striking distance","") | M30: 0 | N30: 0 | O30: 0 | P30: 46244 | Q30: Commercial → launch post hub. 2026-06-18.
A31: bella vita lipa rental | B31: Cluster 6 - Branded / Property | C31: Local/Branded | D31: Medium | E31: Secondary | F31: https://blog.haveninlipa.com/mickey-in-lipa-coming-soon/ | G31: https://blog.haveninlipa.com/mickey-in-lipa-coming-soon/ | H31: 13 | I31: Published | J31: Y | K31: 0 | L31: =IF(AND(K31>=11,K31<=20),"Striking distance","") | M31: 0 | N31: 0 | O31: 0 | P31: 46244 | Q31: Local/Branded → launch post hub. 2026-06-18.
A32: family weekend batangas | B32: Cluster 3 - Weekend Getaway / Audience | C32: Commercial | D32: High | E32: Primary | F32: https://blog.haveninlipa.com/family-weekend-batangas-without-beach-crowds/ | G32: https://blog.haveninlipa.com/family-weekend-batangas-without-beach-crowds/ | H32: 14 | I32: Published | J32: Y | K32: 0 | L32: =IF(AND(K32>=11,K32<=20),"Striking distance","") | M32: 0 | N32: 0 | O32: 0 | P32: 46244
A33: weekend near manila with family | B33: Cluster 3 - Weekend Getaway / Audience | C33: Commercial | D33: High | E33: Secondary | F33: https://blog.haveninlipa.com/family-weekend-batangas-without-beach-crowds/ | G33: https://blog.haveninlipa.com/family-weekend-batangas-without-beach-crowds/ | H33: 14 | I33: Published | J33: Y | K33: 0 | L33: =IF(AND(K33>=11,K33<=20),"Striking distance","") | M33: 0 | N33: 0 | O33: 0 | P33: 46244
A34: batangas without beach crowds | B34: Cluster 3 - Weekend Getaway / Audience | C34: Informational | D34: Medium | E34: Secondary | F34: https://blog.haveninlipa.com/family-weekend-batangas-without-beach-crowds/ | G34: https://blog.haveninlipa.com/family-weekend-batangas-without-beach-crowds/ | H34: 14 | I34: Published | J34: Y | K34: 0 | L34: =IF(AND(K34>=11,K34<=20),"Striking distance","") | M34: 0 | N34: 0 | O34: 0 | P34: 46244
A35: lipa family itinerary | B35: Cluster 4 - Travel Planning & Logistics | C35: Informational | D35: Medium | E35: Secondary | F35: https://blog.haveninlipa.com/family-weekend-batangas-without-beach-crowds/ | G35: https://blog.haveninlipa.com/family-weekend-batangas-without-beach-crowds/ | H35: 14 | I35: Published | J35: Y | K35: 0 | L35: =IF(AND(K35>=11,K35<=20),"Striking distance","") | M35: 0 | N35: 0 | O35: 0 | P35: 46244
A36: independence day long weekend lipa | B36: Cluster 3 - Weekend Getaway / Audience | C36: Seasonal | D36: High | E36: Primary | F36: https://blog.haveninlipa.com/independence-day-long-weekend-lipa-2026/ | G36: https://blog.haveninlipa.com/independence-day-long-weekend-lipa-2026/ | H36: 15 | I36: Published | J36: Y | K36: 0 | L36: =IF(AND(K36>=11,K36<=20),"Striking distance","") | M36: 0 | N36: 0 | O36: 0 | P36: 46244 | Q36: PRIMARY. Holiday long-tail; deliberately NOT generic 'weekend getaway near manila' (#3) to avoid cannibalization.
A37: independence day getaway near manila 2026 | B37: Cluster 3 - Weekend Getaway / Audience | C37: Seasonal | D37: Medium | E37: Secondary | F37: https://blog.haveninlipa.com/independence-day-long-weekend-lipa-2026/ | G37: https://blog.haveninlipa.com/independence-day-long-weekend-lipa-2026/ | H37: 15 | I37: Published | J37: Y | K37: 0 | L37: =IF(AND(K37>=11,K37<=20),"Striking distance","") | M37: 0 | N37: 0 | O37: 0 | P37: 46244 | Q37: Secondary.
A38: araw ng kalayaan weekend itinerary | B38: Cluster 3 - Weekend Getaway / Audience | C38: Informational | D38: Low | E38: Secondary | F38: https://blog.haveninlipa.com/independence-day-long-weekend-lipa-2026/ | G38: https://blog.haveninlipa.com/independence-day-long-weekend-lipa-2026/ | H38: 15 | I38: Published | J38: Y | K38: 0 | L38: =IF(AND(K38>=11,K38<=20),"Striking distance","") | M38: 0 | N38: 0 | O38: 0 | P38: 46244 | Q38: Secondary (Tagalog variant).
A39: what to do in lipa when it rains | B39: Cluster 2 - Things to Do in Lipa | C39: Informational | D39: Medium | E39: Primary | F39: https://blog.haveninlipa.com/indoor-things-to-do-in-lipa-city-when-it-rains/ | G39: https://blog.haveninlipa.com/indoor-things-to-do-in-lipa-city-when-it-rains/ | H39: 16 | I39: Published | J39: Y | K39: 0 | L39: =IF(AND(K39>=11,K39<=20),"Striking distance","") | M39: 0 | N39: 0 | O39: 0 | P39: 46244 | Q39: PRIMARY. Rainy/indoor variant; NOT 'things to do in lipa city' (owned by #1) to avoid cannibalization.
A40: indoor things to do in lipa city | B40: Cluster 2 - Things to Do in Lipa | C40: Informational | D40: Medium | E40: Secondary | F40: https://blog.haveninlipa.com/indoor-things-to-do-in-lipa-city-when-it-rains/ | G40: https://blog.haveninlipa.com/indoor-things-to-do-in-lipa-city-when-it-rains/ | H40: 16 | I40: Published | J40: Y | K40: 0 | L40: =IF(AND(K40>=11,K40<=20),"Striking distance","") | M40: 0 | N40: 0 | O40: 0 | P40: 46244 | Q40: Secondary.
...

Sheet To Do with Keywords
A1: Question, once we generate the appropriate keywords for the articles, they are placed in the keyword tracker - then other that checking them regularly in GSC, what should be done with those keywords?
A3: Great question — and the answer is the difference between a tracker that's a graveyard of numbers and one that's a work queue. Monitoring is step zero; here's what the keywords are actually for once they're in the sheet:
A5: 1. Put the keyword into the page (at publish time)
A7: Each tracker row maps a keyword → a target URL. That keyword should then be deployed on that page:
A9: Yoast focus keyphrase (you already use these), title tag, H1, URL slug, first ~100 words, one or two H2s, an image alt, and the meta description.
A10: One primary keyphrase per article + a few secondaries. The tracker is your dedup ledger — before assigning a keyword, confirm no other live page already owns it (prevents cannibalization, where two of your pages compete and split the ranking).
A12: 2. Wire internal links by cluster (hub-and-spoke)
A14: This is the highest-leverage use and exactly your moat. The Cluster column tells you which articles relate:
A16: Cluster-mates link to each other; all of them link up to money pages (the property pages + the Book-Direct article #6) using the keyword as natural anchor text.
A17: This is literally what the audit prescribed for #28 (road-trip hub linking #1/#4/#5/#7/#10). The keyword map is your linking blueprint.
A19: 3. Turn position into a prioritized to-do list
A21: Don't just record positions — let them trigger work:
A22: GSC position | B22: What it means | C22: Action
A23: 11-20 (page 2) | B23: "Striking distance" — best ROI | C23: Refresh/expand the article, add internal links, sharpen the title → push to page 1
A24: 46122 | B24: On page 1, not top | C24: Improve title/meta for clicks; add schema; earn a couple links
A25: 46025 | B25: Winning | C25: Maintain; watch for decay/cannibalization
A26: Not ranking / not indexed | B26: Technical or thin | C26: Check indexing, canonical, content depth
A28: 4. Fix CTR where impressions are high but clicks aren't
A30: When the tracker shows high impressions, low CTR, the ranking is fine — the title tag + meta description aren't earning the click. Rewrite them (and confirm schema for rich results). This is often faster wins than chasing new rankings.
A32: 5. Mine GSC for the queries you didn't target
A34: In GSC → Performance, filter to each page: it shows the actual search queries bringing impressions — usually far more than your one target keyword. Harvest those:
A36: New secondary keywords to add to the page,
A37: New FAQ entries,
A38: New article ideas for the next cycle. This is how the keyword list keeps growing organically instead of going stale.
A40: 6. Refresh on a cadence + tie to bookings
A42: Seasonal / dated keywords (e.g. "2026" guides, "summer in lipa") need scheduled refreshes — the audit already pre-scheduled the "Things to Do" refresh for Aug 31. Use Last Reviewed to find decaying pages.
A43: Prioritize by intent → revenue: Cluster 1 (transactional) and Cluster 5 (direct booking) keywords sit closest to a booking, so optimization effort there matters most. Ultimately tie ranking pages back to the audit's real KPI — direct-booking inquiries vs. OTA.
A47: In one line: a keyword's job is rank → attract → internally link to a property page → convert — and the tracker's position/CTR/impression columns tell you which lever to pull next.
A48: If it'd help, I can add a couple of operational columns to the synced tracker to make this automatic — e.g. a "Striking Distance?" flag (auto-highlights positions 11-20) and an on-page checklist column (focus kw / title / H1 / internal links / schema ✓). Want me to build that in?
A52: On-page element | B52: Which keyword
A53: Yoast Focus Keyphrase | B53: The primary (Yoast only allows one focus keyphrase)
A54: Title tag | B54: Primary — near the front
A55: H1 | B55: Primary
A56: URL slug | B56: Primary (but never change a slug on an already-published page — it breaks the URL)
A57: First ~100 words | B57: Primary
A58: H2 headings | B58: Primary in one H2; secondaries in other H2s
A59: Image alt text | B59: Primary on the featured image; secondaries on other images
A60: Meta description | B60: Primary + one secondary, written to earn the click

Sheet Priority Focus (60-Day)
A1: # | B1: Keyword / Keyphrase | C1: Target Page | D1: Next Action
A2: 1 | B2: family staycation lipa | C2: Article #11 (live) | D2: Internal links from #1, #3, #5; refresh meta description; request indexing in GSC.
A3: 2 | B3: romantic getaway batangas | C3: Article #12 (live) | D3: Add Tagaytay comparison schema; FAQ markup; cross-link from 1BR property page.
A4: 3 | B4: book direct vs airbnb | C4: Article #6 (live) | D4: Add price comparison table; link from homepage and every property page footer.
A5: 4 | B5: how to get to lipa from manila | C5: Article #10 (live, indexed) | D5: LIVE + indexed (confirmed 2026-07-04). Monitor position; build long-tail internal links.
A6: 5 | B6: things to do in lipa city | C6: Article #1 (live) | D6: Add Mt Maculot + Taal viewpoint as H2s; refresh image alt text.
A7: 6 | B7: family weekend batangas | C7: Article #14 (NEW) | D7: Push for indexing; promote in HavenInLipa newsletter; link to 2BR property page.
A8: 7 | B8: batangas without beach crowds | C8: Article #14 (NEW) | D8: Differentiator angle - low competition. Promote in Q3 when Laiya/Nasugbu traffic peaks.
A9: 8 | B9: mickey in lipa | C9: Article #13 + new property page | D9: DONE — 3 config pages live (sleeps 7/11/15, real photos, schema). Next: internal links from #11/#14 + finish launch-post wiring; monitor GSC.
A10: 9 | B10: disney-inspired house lipa | C10: Article #13 | D10: Property live. Monitor brand SERP weekly; consider Google Ads brand-protect.
A11: 10 | B11: haven in lipa | C11: Homepage | D11: Brand SERP - confirm site shows for this query; if not, GSC -> Request indexing for homepage.
A12: — CONVERSION PRIORITIES (added 2026-07-04, delta run 070426) —
A13: C1 | B13: property page reviews | C13: All property pages | D13: ✅ EXPANDED (verified 2026-08-09): Mickey reviews now 3/4/3 (was 1/2/1). Remaining: per-review star ratings + aggregate line + Review/AggregateRating schema; add reviews to 1BR/2BR.
A14: C2 | B14: blog to booking funnel | C14: Top articles #1/#11/#12/#14 | D14: ✅ DONE (verified 2026-08-09): CTAs extended to pre-June evergreens #1/#3/#7 (after-intro callout + 5-property box; #1 used the drafted copy). Remaining: #5/#10; a couple mid-article 'Where to Stay' mentions still 1BR/2BR-only.
A15: C3 | B15: conversion tracking | C15: Site-wide (GA4) | D15: ✅ SHIPPED (verified 2026-08-09): GA4 G-2SV2PXYB7T live on both domains; check_availability data-hooks in HTML. TODO: confirm booking_confirmed/book_click in GA4 DebugView + mark key events; finish generate_lead.
A16: C4 | B16: email capture / lead magnet | C16: Blog | D16: Add 'Lipa Weekend Planner' lead magnet + capture forms + 4-email nurture (Fix #4).
A17: C5 | B17: booking friction (4 fixes) | C17: Property pages / cards | D17: ✅ DONE (verified 2026-08-09): cards 'Check Availability' (0 'View Details'); itemized DB fees ('covers N', extra-guest, 'no hidden fees'); sticky booking CTA. Deposit/partial intentionally excluded. Check: remaining 'Additional charge' strings are itemized not vague.

Sheet Page Indexing Tracker
A1: URL | B1: Page Type | C1: Linked Cluster / Keywords | D1: Indexing Status | E1: Last Crawled (GSC) | F1: Last Checked (you) | G1: Action Needed | H1: Notes
A2: https://haveninlipa.com/ | B2: Homepage | C2: Brand SERP + Cluster 1 transactional | D2: Indexed | E2: 2026-06-24 | F2: 2026-07-04 | G2: Monitor weekly for brand term ranking | H2: Verified indexed (GSC May 18, 2026). Brand SERP + Cluster 1.
A3: https://www.haveninlipa.com/ | B3: Homepage (www) | C3: Same as apex | D3: Not indexed – canonicalized | E3: 2026-04-18 | F3: 2026-06-02 | G3: OK — no longer separately indexed; canonicalized to apex. Duplicate-content concern resolved. | H3: Not present in May 2026 GSC indexed set (only apex). Good outcome.
A4: https://haveninlipa.com/properties/spacious-2-bedroom | B4: Property page | C4: Cluster 1 (transactional) | D4: Indexed | E4: 2026-06-26 | F4: 2026-07-04 | G4: Expand to 1,500+ words per May 8 strategy report | H4: Verified indexed (GSC May 17, 2026).
A5: https://haveninlipa.com/properties/cozy-1-bedroom | B5: Property page | C5: Cluster 1 (transactional) + couple keywords | D5: Indexed | E5: 2026-06-26 | F5: 2026-07-04 | G5: Expand to 1,500+ words; feature 1BR for couples | H5: Verified indexed (GSC May 17, 2026).
A6: https://haveninlipa.com/about | B6: About page | C6: Brand SERP | D6: Indexed | E6: 2026-05-17 | F6: 2026-07-04 | G6: Add author credentials and local Lipa story for E-E-A-T | H6: Verified indexed (GSC May 17, 2026).
A7: https://haveninlipa.com/faq | B7: FAQ page | C7: Brand SERP + multiple long-tail | D7: Indexed | E7: 2026-06-24 | F7: 2026-07-04 | G7: Add FAQ schema markup for rich results | H7: Verified indexed (GSC May 8, 2026)
A8: https://haveninlipa.com/privacy | B8: Legal | C8: N/A | D8: Indexed | E8: 2026-06-24 | F8: 2026-07-04 | G8: No action needed | H8: Verified indexed (GSC May 8, 2026)
A9: https://haveninlipa.com/terms | B9: Legal | C9: N/A | D9: Indexed | E9: 2026-05-08 | F9: 2026-07-04 | G9: No action needed | H9: Verified indexed (GSC May 8, 2026)
A10: https://blog.haveninlipa.com/ | B10: Blog index | C10: All blog clusters | D10: Indexed | E10: 2026-06-25 | F10: 2026-07-04 | G10: Ensure latest article is featured at top; sticky 'Book Direct' CTA | H10: Verified indexed (GSC May 17, 2026).
A11: https://blog.haveninlipa.com/category/booking-tips/ | B11: Blog category | C11: Cluster 5 (direct booking) | D11: noindexed | E11: 2026-04-30 | G11: Add intro copy to category page (currently thin) | H11: Verified indexed (GSC Apr 30, 2026)
A12: https://blog.haveninlipa.com/holy-week-in-lipa-city-batangas-a-peaceful-retreat-near-manila/ | B12: Blog article #8 | C12: holy week getaway lipa | D12: Indexed | E12: 2026-05-06 | F12: 2026-07-04 | G12: Evergreen reframe DONE (live, index,follow, in sitemap). Re-promote ~Feb 2027 for Holy Week. | H12: Confirmed live 200 + in post-sitemap 2026-06-18. Was 404 mid-June; restored as evergreen.
A13: https://blog.haveninlipa.com/15-best-things-to-do-in-lipa-city-batangas-2026-locals-guide/ | B13: Blog article #1 | C13: Cluster 2 (things to do) | D13: Indexed | E13: 2026-05-17 | F13: 2026-07-04 | G13: None — confirmed indexed (GSC). Monitor weekly. | H13: Targets: things to do in lipa city, lipa city tourist spots, lipa batangas attractions. URL synced to live slug 2026-06-02.
A14: https://blog.haveninlipa.com/weekend-getaway-in-lipa-city-batangas-your-chill-escape-near-manila/ | B14: Blog article #3 | C14: Cluster 3 (weekend getaway) | D14: Indexed | E14: 2026-06-29 | F14: 2026-07-04 | G14: None — confirmed indexed (GSC). Monitor weekly. | H14: Targets: weekend getaway near manila. URL synced to live slug 2026-06-02.
A15: https://blog.haveninlipa.com/mt-maculot-hiking-guide-2026-trail-tips-routes-where-to-stay-in-lipa/ | B15: Blog article #4 | C15: Cluster 2 (informational) | D15: Indexed | E15: 2026-06-29 | F15: 2026-07-04 | G15: None — confirmed indexed (GSC). Monitor weekly. | H15: Targets: mt maculot hiking guide. URL synced to live slug 2026-06-02.
A16: https://blog.haveninlipa.com/best-restaurants-cafes-in-lipa-city-batangas-2026-food-guide/ | B16: Blog article #5 | C16: Cluster 4 (food/travel planning) | D16: Indexed | E16: 2026-06-26 | F16: 2026-07-04 | G16: None — confirmed indexed (GSC). Monitor weekly. | H16: Targets: best restaurants in lipa, lipa city food trip. URL synced to live slug 2026-06-02.
A17: https://blog.haveninlipa.com/why-book-direct-instead-of-airbnb-a-philippines-hosts-honest-take/ | B17: Blog article #6 | C17: Cluster 5 (direct booking) - HIGH priority | D17: Indexed | E17: 2026-05-19 | F17: 2026-07-04 | G17: None — confirmed indexed (GSC). Monitor weekly. | H17: Targets: book direct vs airbnb, save on vacation rental fees, airbnb alternative lipa. URL synced to live slug 2026-06-02.
A18: https://blog.haveninlipa.com/taal-volcano-day-trip-from-lipa-city-2026-updated-guide/ | B18: Blog article #7 | C18: Cluster 2 (day trip) | D18: Indexed | E18: 2026-06-29 | F18: 2026-07-04 | G18: None — confirmed indexed (GSC). Monitor weekly. | H18: Targets: taal volcano day trip from lipa. URL synced to live slug 2026-06-02.
A19: https://blog.haveninlipa.com/work-from-lipa-the-affordable-remote-work-staycation-near-manila/ | B19: Blog article #9 | C19: Cluster 3 (remote work) | D19: Indexed | E19: 2026-06-26 | F19: 2026-07-04 | G19: None — confirmed indexed (GSC). Monitor weekly. | H19: Targets: remote work staycation philippines, work from lipa. URL synced to live slug 2026-06-02.
A20: https://blog.haveninlipa.com/how-to-get-to-lipa-city-from-manila-2026-guide/ | B20: Blog article #10 | C20: Cluster 4 (logistics) | D20: Indexed | E20: 2026-06-28 | F20: 2026-07-04 | G20: Indexed ✓ (GSC 2026-06-28) — monitor. | H20: Targets: how to get to lipa from manila, lipa city travel guide. Was reported 404; confirmed live + indexed 2026-06-02. | Confirmed indexed (GSC crawl 2026-06-28); verified 2026-07-04.
A21: https://blog.haveninlipa.com/family-staycation-lipa-city-batangas/ | B21: Blog article #11 | C21: Cluster 3 (family) - HIGH priority | D21: Indexed | E21: 2026-06-28 | F21: 2026-07-04 | G21: Confirm indexed in next GSC pull. | H21: Live slug confirmed 2026-06-18 (family-staycation-lipa-city-batangas). In sitemap.
A22: https://blog.haveninlipa.com/romantic-getaway-batangas-lipa-city/ | B22: Blog article #12 | C22: Cluster 3 (couples) - HIGH priority | D22: Indexed | E22: 2026-06-26 | F22: 2026-07-04 | G22: Confirm indexed in next GSC pull. | H22: Live slug confirmed 2026-06-18 (romantic-getaway-batangas-lipa-city). In sitemap.
A23: https://blog.haveninlipa.com/mickey-in-lipa-coming-soon/ | B23: Blog article #13 | C23: Cluster 6 (Mickey in Lipa launch) | D23: Indexed | E23: 2026-06-28 | F23: 2026-07-04 | G23: Confirm indexed in next GSC pull. | H23: Now a LAUNCH post (top update + links to 3 live config pages). Real photos live. Slug: mickey-in-lipa-coming-soon.
... A25: https://haveninlipa.com/properties/mickey-in-lipa--family-staycation--sleeps-7 | B25: Property page (Mickey) | C25: Cluster 6 / Cluster 1 — Mickey sleeps 7 | D25: Indexed | E25: 2026-06-25 | F25: 2026-07-04 | G25: Indexed ✓ (GSC 2026-06-25) — monitor. | H25: Mickey sleeps up to 7 (rate covers 5). ₱2,400/night, real photos. Live 2026-06-18. | Confirmed indexed (GSC crawl 2026-06-25); verified 2026-07-04.
A26: https://blog.haveninlipa.com/barkada-getaway-near-manila-why-a-whole-house-in-lipa-beats-a-beach-resort-cost-per-head-math-inside/ | B26: Blog article #27 | C26: Cluster 3 (barkada) | D26: Live – verify GSC | F26: 2026-08-09 | G26: Published — in sitemap (lastmod 2026-08-10); confirm GSC indexing. | H26: Barkada gap article now LIVE; live slug lengthened vs planned 'barkada-getaway-lipa-whole-house-near-manila'. Mickey CTAs added to draft 2026-08-09.
A27: (TBD) https://blog.haveninlipa.com/summer-in-lipa-2026/ | B27: Future seasonal LP | C27: Cluster 3 (seasonal) | D27: Page Not Published | G27: Publish before May-June 2026 peak; landing page format | H27: Targets: summer in lipa 2026
A28: (TBD) https://blog.haveninlipa.com/batangas-road-trip-itinerary/ | B28: Future hub article | C28: Cluster 4 (travel planning) | D28: Page Not Published | G28: Write during Tier C window; will interlink with #1, #4, #5, #7, #10 | H28: Targets: batangas road trip itinerary
A29: (TBD) https://blog.haveninlipa.com/senior-friendly-lipa-getaway/ | B29: Future article (Tier D) | C29: Cluster 3 (audience) | D29: Page Not Published | G29: Write during Q3 2026 authority phase | H29: Targets: senior-friendly lipa getaway
A30: (TBD) https://blog.haveninlipa.com/solo-travel-guide-lipa/ | B30: Future article (Tier D) | C30: Cluster 3 (audience) | D30: Page Not Published | G30: Write during Q3 2026 authority phase | H30: Targets: solo travel guide to lipa
A31: https://blog.haveninlipa.com/tag/barako-coffee/ | B31: Tag archive | C31: Thin / none (heritage tag) | D31: noindexed | E31: 2026-05-18 | F31: 2026-07-04 | G31: Add noindex,follow to /tag/ archives (low-priority cleanup; thin pages). | H31: noindex,follow CONFIRMED LIVE in raw HTML 2026-07-04 — pending drop from index on next Google crawl. (/tag/barako-coffee/)
A32: https://blog.haveninlipa.com/tag/batangas/ | B32: Tag archive | C32: Thin / none | D32: noindexed | E32: 2026-05-18 | F32: 2026-07-04 | G32: Add noindex,follow to /tag/ archives (low-priority cleanup; thin pages). | H32: noindex,follow re-confirmed live in raw HTML 2026-07-04 — pending drop on next crawl.
A33: https://blog.haveninlipa.com/tag/airbnb/ | B33: Tag archive | C33: Thin / none | D33: noindexed | E33: 2026-05-18 | F33: 2026-07-04 | G33: Add noindex,follow to /tag/ archives (low-priority cleanup; thin pages). | H33: noindex,follow CONFIRMED LIVE in raw HTML 2026-07-04 — pending drop from index on next Google crawl. (/tag/airbnb/)
A34: https://blog.haveninlipa.com/author/cassandrakim/ | B34: Author archive | C34: E-E-A-T author signal | D34: noindexed | E34: 2026-05-17 | F34: 2026-07-04 | G34: Add noindex,follow to /author/ archives (thin) OR build out author bio for E-E-A-T. | H34: noindex,follow CONFIRMED LIVE in raw HTML 2026-07-04 — pending drop from index on next Google crawl. (/author/cassandrakim/)
A35: https://blog.haveninlipa.com/independence-day-long-weekend-lipa-2026/ | B35: Blog article #15 | C35: Cluster 3 (seasonal/holiday) | D35: Indexed | E35: 2026-06-18 | F35: 2026-07-04 | G35: Indexed ✓ (GSC 2026-06-18) — monitor. | H35: Published Mon Jun 8 2026. Live + in sitemap 2026-06-18. | Confirmed indexed (GSC crawl 2026-06-18); verified 2026-07-04.
A36: https://blog.haveninlipa.com/indoor-things-to-do-in-lipa-city-when-it-rains/ | B36: Blog article #16 | C36: Cluster 2 (rainy-day things to do) | D36: Live – verify GSC | F36: 2026-08-09 | G36: Published & in sitemap; confirm GSC indexing. | H36: #16 rainy-day — live.
A37: https://blog.haveninlipa.com/lipa-barako-coffee-heritage/ | B37: Blog article #17 | C37: Cluster 2 (heritage) | D37: Indexed | E37: 2026-06-22 | F37: 2026-07-04 | G37: Indexed ✓ (GSC 2026-06-22) — monitor. | H37: Primary target: lipa barako coffee. Drafted in 050826/; blogger guide embedded. | Confirmed indexed (GSC crawl 2026-06-22); verified 2026-07-04. Live slug is /lipa-barako-coffee-heritage/ (shorter than planned; slug drift corrected).
A38: https://blog.haveninlipa.com/best-lomi-lipa-city/ | B38: Blog article #18 | C38: Cluster 4 (food) | D38: Live – verify GSC | F38: 2026-07-04 | G38: Request indexing in GSC; confirm in next pull. | H38: Published Mon Jun 29 2026. Delta 2026-07-04: confirmed live 200 + index,follow + Article schema + in post-sitemap. SLUG DRIFT CORRECTED: planned best-lomi-lipa-city-local-guide -> live best-lomi-lipa-city.
A39: https://blog.haveninlipa.com/work-from-lipa-rainy-season-july/ | B39: Blog article #19 | C39: Cluster 3 (remote work) | D39: Live – verify GSC | F39: 2026-08-09 | G39: Published & in sitemap; confirm GSC indexing. | H39: #19 work-from-lipa (rainy) — live.
A40: https://blog.haveninlipa.com/lipa-vs-tagaytay-an-honest-comparison-from-a-host-who-lives-in-lipa/ | B40: Blog article #20 | C40: Cluster 3 (comparison) | D40: Live – verify GSC | F40: 2026-08-09 | G40: Published & in sitemap; confirm GSC indexing. Slug drift corrected 2026-08-09. | H40: #20 — live slug lengthened vs planned 'lipa-vs-tagaytay-honest-comparison'.
A41: https://blog.haveninlipa.com/casa-de-segunda-lipa-city/ | B41: Blog article #21 | C41: Cluster 2 (heritage) | D41: Live – verify GSC | F41: 2026-08-09 | G41: Published & in sitemap; confirm GSC indexing. Slug drift corrected 2026-08-09. | H41: #21 — live slug 'casa-de-segunda-lipa-city' (was '...-heritage-walk').
...

Sheet GSC Setup Steps
B2: Google Search Console - Setup & Weekly Workflow
B3: Do steps A-B once. Steps C-G run on a recurring weekly/monthly cadence.
B5: A. Verify HavenInLipa.com is added to Google Search Console
B6: 1. Go to https://search.google.com/search-console
B7: 2. Sign in with the Google account that owns/manages HavenInLipa.com.
B8: 3. Top-left -> property dropdown -> Add Property -> URL prefix -> enter https://haveninlipa.com
B9: 4. Verify ownership: easiest is DNS TXT record (via your domain registrar) or HTML tag (paste into <head> of homepage).
B10: 5. Once verified, also add the www. version if applicable, and select the preferred domain.
B12: B. Submit your sitemap
B13: 1. In GSC left sidebar -> Sitemaps.
B14: 2. Enter: sitemap.xml (or /wp-sitemap.xml if WordPress) -> Submit.
B15: 3. Confirm 'Success' status appears within 24-48 hours.
... B46: 3. This builds your historical trend file. After 3 months you can see real movement.

Sheet GSC Troubleshooting
B2: GSC Troubleshooting - When Keywords Show No Data
B3: Use this sheet whenever a keyword in Keyword Master is not showing data in Search Console.
B5: Quick context (read first)
B6: Google Search Console is PASSIVE reporting, not active keyword tracking. Searching for a keyword inside GSC does NOT 'add' or 'save' it.
B7: GSC only shows queries where (a) someone actually searched on Google, (b) your site appeared in the results, and (c) at least one impression was recorded during your selected date range.
B8: If a keyword shows no data, it usually means the page is not indexed yet, the page is not ranking in the top ~100, the content is too new, or the keyword has very low monthly search volume in the Philippines.
B10: Decision tree - if a keyword shows zero data in GSC
B11: STEP 1: Check if the page exists and is reachable.
B12: - Paste the target URL into a browser. Does it load? If 404 -> the page must be published first.
B13: STEP 2: Check if the page is indexed.
B14: - GSC -> URL Inspection bar (top) -> paste the full URL.
B15: - 'URL is on Google' = indexed. Proceed to Step 3.
... B75: 4. PageSpeed Insights - free - flags page speed issues that hurt rankings.

Sheet Blogger Brief
B2: Blogger Brief - How to Use This Keyword List
B3: Read top-to-bottom before writing your first HavenInLipa article. Refer back every time.
B5: How to read this workbook before writing
B6: 1. Open the 'Keyword Master' sheet. Find the row(s) for the article you are about to write.
B7: 2. Note the PRIMARY keyword (the keyword the article is titled around) and 2-4 SUPPORTING keywords from the same cluster.
B8: 3. Note the SEARCH INTENT - this tells you what the reader expects to do/learn. Match the article's promise to that intent.
B9: 4. Note the TARGET URL - this is the slug to publish under. Do not change it without checking with the SEO lead.
B11: Where each keyword goes in the article (use this checklist)
B12: PRIMARY KEYWORD:
B13: - In the H1 title (naturally - never forced).
B14: - In the first 100 words of the intro.
B15: - In the meta description (1 time, naturally).
... B61: Article #10 (How to Get There - PUBLISH): how to get to lipa from manila | lipa city travel guide

Sheet Tracking Log Template
A1: Keyword | B1: Snapshot Date (YYYY-MM) | C1: Avg. Position | D1: Impressions | E1: Clicks | F1: CTR % | G1: Movement vs. last month | H1: Notes
A2: short term rental lipa city
A3: vacation rental lipa batangas
A4: airbnb alternative lipa
A5: affordable staycation lipa
A6: direct booking lipa city
A7: full house rental lipa
A8: family house rental lipa city
A9: things to do in lipa city
A10: lipa city tourist spots
A11: lipa batangas attractions
A12: mt maculot hiking guide
A13: taal volcano day trip from lipa
... A47: haven in lipa

Sheet Lists
A1: Value | B1: Meaning
A2: Indexed | B2: URL Inspection says "URL is on Google"
A3: Not Indexed - Requested | B3: You clicked Request Indexing; waiting on Google
A4: Not Indexed | B4: Page is not on Google, no request sent yet
A5: Crawled Not Indexed | B5: Google saw it and declined — content needs improvement
A6: Discovered Not Indexed | B6: Google knows but hasn't crawled — needs internal links
A7: Page Not Published | B7: No live URL exists yet (gap/draft keywords)
A8: N/A - Brand Term | B8: Homepage / brand-only keywords
